Workbook

Sheet ИНСТРУКЦИЯ
A1: LAB-03 / RISC-V ПОД МИКРОСКОПОМ
A3: Excel Observatory • PicoRV32 / Tang Nano 9K • 12 настоящих T3-снимков • RV32I
A4: СТАРТ | B4: НАБЛЮДЕНИЕ | C4: СРАВНЕНИЕ | D4: LED / MMIO | E4: КОМАНДЫ | F4: 12 ТРАСС | G4: RAW T3 | H4: ROM | I4: ТЕРМИНЫ | J4: ПРОИСХОЖДЕНИЕ | K4: БИТЫ 202 | L4: 10 КАРТОЧЕК
A6: КАК РАБОТАЕТ ДЕМОНСТРАЦИОННАЯ МОДЕЛЬ
B8: 01 · НАБЛЮДЕНИЕ | E8: Откройте «ПУЛЬТ». Желтые ячейки D6 и I6 — выбираются номер аппаратной трассы и номер события. Пошагово исследуйте FETCH и финальную запись LED_WRITE.
B9: 02 · ПОВТОРЯЕМОСТЬ | E9: Откройте «ЗАХВАТЫ» и график 12 запусков. Для одной и той же UART-команды число FETCH может изменяться из-за ожидания байта.
B10: 03 · СОПОСТАВЛЕНИЕ | E10: Откройте «СРАВНЕНИЕ». Исходно выбраны захваты 03 и 05 команды 4: 24 против 28 FETCH, но нормализованный CORE совпадает.
B11: 04 · КОМАНДЫ RV32I | E11: Откройте «КОМАНДЫ», найдите sw, а затем «ROM LAB03». Все примеры взяты из нашего ROM и аппаратных FETCH, а не придуманы.
B12: 05 · МОДЕЛЬ MMIO | E12: Откройте «МОДЕЛЬ MMIO»: выбирайте 0…6 и наблюдайте вычисляемую маску GPIO при НЕИЗМЕННОМ машинном коде sw.
B13: 06 · ПРОИСХОЖДЕНИЕ | E13: Трассы импортированы из проверенного архивного ZIP. Лист «ИСТОЧНИКИ» содержит хеши, ссылки и ограничения доказательства.
B14: 07 · БИТОВЫЙ ДЕКОДЕР | E14: Новый лист «РАЗБОР RV32I»: источник ТРАССА автоматически повторяет FETCH из ПУЛЬТА. В режиме РОМ индекс 1…202 выбирает любое рабочее слово.
B15: 08 · КАРТОЧКИ | E15: Лист «10 КАРТОЧЕК» подробно показывает битовые поля каждого типа команды на настоящем машинном слове; «КАТАЛОГ БИТОВ» раскрывает все 202 адреса.
A16: ТРЁХМИНУТНЫЙ ВИДЕОЭКСПЕРИМЕНТ
B18: 1. На «ПУЛЬТ» выберите захват 05, событие 27: PC=0x00000100, WORD=0x01D2A023, sw t4,0(t0).
B19: 2. Измените номер события на 28: fetch инструкции lw t6,0(t0). Затем 29: LED_WRITE по 0x20000000 со значением 0x00000008.
B20: 3. На «СРАВНЕНИЕ» убедитесь: захваты 03 и 05 различаются 24/28 FETCH, но совпадают по 23 событиям от PC=0x048 до LED_WRITE.
B21: 4. На «МОДЕЛЬ MMIO» замените команду 4 на 5: маска станет 0x10, а машинное слово sw останется 0x01D2A023.
B24: ВАЖНО: Excel — офлайн-проигрыватель реальных сохранённых шинных событий. Он НЕ соединяется с COM, НЕ программирует FPGA, НЕ измеряет исполнение в реальном времени. FETCH ≠ retirement; модель MMIO ≠ аппаратное измерение.
B28: Исходник: https://github.com/AIDevelopersMonster/Sipeed-FPGA/tree/feature/picorv32-lab03-uart-trace/docs/lab03/observatory ROM SHA-256: 14b85bc20ce43cdf4ce09ef1db7a20af5677c1c728c64b71258f6c63ab5b8a3d

Sheet ДАННЫЕ T3
A1: АППАРАТНЫЕ ДАННЫЕ / T3 RAW
A3: 281 событий из 12 физических запусков • импорт исходных T3-кадров • не синтетические циклы
A4: СТАРТ | B4: НАБЛЮДЕНИЕ | C4: СРАВНЕНИЕ | D4: LED / MMIO | E4: КОМАНДЫ | F4: 12 ТРАСС | G4: RAW T3 | H4: ROM | I4: ТЕРМИНЫ | J4: ПРОИСХОЖДЕНИЕ | K4: БИТЫ 202 | L4: 10 КАРТОЧЕК
A5: Захват | B5: UART | C5: № (Excel) | D5: Цикл T3 | E5: Событие | F5: PC / адрес | G5: WORD / DATA | H5: Ассемблер | I5: Мнемоника | J5: Участок | K5: Ключ | L5: Сигнатура | M5: MNEM+PC | N5: 1-й PC | O5: ROM-check | P5: Префикс | Q5: Оригинал E:…
A6: 1 | B6: 4 | C6: 1 | D6: 1 | E6: FETCH | F6: 0x0000003C | G6: 0x0013F393 | H6: andi t2, t2, 1 | I6: andi | J6: POLL | K6: 1001 | L6: FETCH|0x0000003C|0x0013F393 | M6: andi@0x0000003C | N6: =IF(E6="FETCH",IF(COUNTIF($M$6:M6,M6)=1,1,0),0) -> 1 | O6: ROM OK | P6: =IF(AND(E6="FETCH",F6="0x00000048"),C6-1,0) -> 0 | Q6: E:00000000:00010001:0000003c:0013f393
A7: 1 | B7: 4 | C7: 2 | D7: 8 | E7: FETCH | F7: 0x00000040 | G7: 0xFE038CE3 | H7: beq t2, zero, 0x00000038 | I7: beq | J7: POLL | K7: 1002 | L7: FETCH|0x00000040|0xFE038CE3 | M7: beq@0x00000040 | N7: =IF(E7="FETCH",IF(COUNTIF($M$6:M7,M7)=1,1,0),0) -> 1 | O7: ROM OK | P7: =IF(AND(E7="FETCH",F7="0x00000048"),C7-1,0) -> 0 | Q7: E:00000001:00010008:00000040:fe038ce3
A8: 1 | B8: 4 | C8: 3 | D8: 12 | E8: FETCH | F8: 0x00000044 | G8: 0x0182AE03 | H8: lw t3, 24(t0) | I8: lw | J8: POLL | K8: 1003 | L8: FETCH|0x00000044|0x0182AE03 | M8: lw@0x00000044 | N8: =IF(E8="FETCH",IF(COUNTIF($M$6:M8,M8)=1,1,0),0) -> 1 | O8: ROM OK | P8: =IF(AND(E8="FETCH",F8="0x00000048"),C8-1,0) -> 0 | Q8: E:00000002:0001000c:00000044:0182ae03
A9: 1 | B9: 4 | C9: 4 | D9: 16 | E9: FETCH | F9: 0x00000048 | G9: 0x05400413 | H9: addi s0, zero, 84 | I9: addi | J9: CORE | K9: 1004 | L9: FETCH|0x00000048|0x05400413 | M9: addi@0x00000048 | N9: =IF(E9="FETCH",IF(COUNTIF($M$6:M9,M9)=1,1,0),0) -> 1 | O9: ROM OK | P9: =IF(AND(E9="FETCH",F9="0x00000048"),C9-1,0) -> 3 | Q9: E:00000003:00010010:00000048:05400413
A10: 1 | B10: 4 | C10: 5 | D10: 23 | E10: FETCH | F10: 0x0000004C | G10: 0x1A8E0063 | H10: beq t3, s0, 0x000001EC | I10: beq | J10: CORE | K10: 1005 | L10: FETCH|0x0000004C|0x1A8E0063 | M10: beq@0x0000004C | N10: =IF(E10="FETCH",IF(COUNTIF($M$6:M10,M10)=1,1,0),0) -> 1 | O10: ROM OK | P10: =IF(AND(E10="FETCH",F10="0x00000048"),C10-1,0) -> 0 | Q10: E:00000004:00010017:0000004c:1a8e0063
A11: 1 | B11: 4 | C11: 6 | D11: 27 | E11: FETCH | F11: 0x00000050 | G11: 0x04300413 | H11: addi s0, zero, 67 | I11: addi | J11: CORE | K11: 1006 | L11: FETCH|0x00000050|0x04300413 | M11: addi@0x00000050 | N11: =IF(E11="FETCH",IF(COUNTIF($M$6:M11,M11)=1,1,0),0) -> 1 | O11: ROM OK | P11: =IF(AND(E11="FETCH",F11="0x00000048"),C11-1,0) -> 0 | Q11: E:00000005:0001001b:00000050:04300413
A12: 1 | B12: 4 | C12: 7 | D12: 31 | E12: FETCH | F12: 0x00000054 | G12: 0x188E0063 | H12: beq t3, s0, 0x000001D4 | I12: beq | J12: CORE | K12: 1007 | L12: FETCH|0x00000054|0x188E0063 | M12: beq@0x00000054 | N12: =IF(E12="FETCH",IF(COUNTIF($M$6:M12,M12)=1,1,0),0) -> 1 | O12: ROM OK | P12: =IF(AND(E12="FETCH",F12="0x00000048"),C12-1,0) -> 0 | Q12: E:00000006:0001001f:00000054:188e0063
A13: 1 | B13: 4 | C13: 8 | D13: 35 | E13: FETCH | F13: 0x00000058 | G13: 0x03F00413 | H13: addi s0, zero, 63 | I13: addi | J13: CORE | K13: 1008 | L13: FETCH|0x00000058|0x03F00413 | M13: addi@0x00000058 | N13: =IF(E13="FETCH",IF(COUNTIF($M$6:M13,M13)=1,1,0),0) -> 1 | O13: ROM OK | P13: =IF(AND(E13="FETCH",F13="0x00000048"),C13-1,0) -> 0 | Q13: E:00000007:00010023:00000058:03f00413
A14: 1 | B14: 4 | C14: 9 | D14: 39 | E14: FETCH | F14: 0x0000005C | G14: 0x0A8E0A63 | H14: beq t3, s0, 0x00000110 | I14: beq | J14: CORE | K14: 1009 | L14: FETCH|0x0000005C|0x0A8E0A63 | M14: beq@0x0000005C | N14: =IF(E14="FETCH",IF(COUNTIF($M$6:M14,M14)=1,1,0),0) -> 1 | O14: ROM OK | P14: =IF(AND(E14="FETCH",F14="0x00000048"),C14-1,0) -> 0 | Q14: E:00000008:00010027:0000005c:0a8e0a63
A15: 1 | B15: 4 | C15: 10 | D15: 43 | E15: FETCH | F15: 0x00000060 | G15: 0x03000413 | H15: addi s0, zero, 48 | I15: addi | J15: CORE | K15: 1010 | L15: FETCH|0x00000060|0x03000413 | M15: addi@0x00000060 | N15: =IF(E15="FETCH",IF(COUNTIF($M$6:M15,M15)=1,1,0),0) -> 1 | O15: ROM OK | P15: =IF(AND(E15="FETCH",F15="0x00000048"),C15-1,0) -> 0 | Q15: E:00000009:0001002b:00000060:03000413
A16: 1 | B16: 4 | C16: 11 | D16: 47 | E16: FETCH | F16: 0x00000064 | G16: 0x048E0463 | H16: beq t3, s0, 0x000000AC | I16: beq | J16: CORE | K16: 1011 | L16: FETCH|0x00000064|0x048E0463 | M16: beq@0x00000064 | N16: =IF(E16="FETCH",IF(COUNTIF($M$6:M16,M16)=1,1,0),0) -> 1 | O16: ROM OK | P16: =IF(AND(E16="FETCH",F16="0x00000048"),C16-1,0) -> 0 | Q16: E:0000000a:0001002f:00000064:048e0463
A17: 1 | B17: 4 | C17: 12 | D17: 51 | E17: FETCH | F17: 0x00000068 | G17: 0x03100413 | H17: addi s0, zero, 49 | I17: addi | J17: CORE | K17: 1012 | L17: FETCH|0x00000068|0x03100413 | M17: addi@0x00000068 | N17: =IF(E17="FETCH",IF(COUNTIF($M$6:M17,M17)=1,1,0),0) -> 1 | O17: ROM OK | P17: =IF(AND(E17="FETCH",F17="0x00000048"),C17-1,0) -> 0 | Q17: E:0000000b:00010033:00000068:03100413
... A30: 1 | B30: 4 | C30: 25 | D30: 102 | E30: FETCH | F30: 0x00000104 | G30: 0x0002AF83 | H30: lw t6, 0(t0) | I30: lw | J30: CORE | K30: 1025 | L30: FETCH|0x00000104|0x0002AF83 | M30: lw@0x00000104 | N30: =IF(E30="FETCH",IF(COUNTIF($M$6:M30,M30)=1,1,0),0) -> 1 | O30: ROM OK | P30: =IF(AND(E30="FETCH",F30="0x00000048"),C30-1,0) -> 0 | Q30: E:00000018:00010066:00000104:0002af83
A31: 1 | B31: 4 | C31: 26 | D31: 105 | E31: LED_WRITE | F31: 0x20000000 | G31: 0x00000008 | H31: MMIO GPIO write | I31: LED_WRITE | J31: MMIO | K31: 1026 | L31: LED_WRITE|0x20000000|0x00000008 | N31: =IF(E31="FETCH",IF(COUNTIF($M$6:M31,M31)=1,1,0),0) -> 0 | O31: MMIO OK | P31: =IF(AND(E31="FETCH",F31="0x00000048"),C31-1,0) -> 0 | Q31: E:00000019:00020069:20000000:00000008
A32: 2 | B32: 0 | C32: 1 | D32: 2 | E32: FETCH | F32: 0x00000044 | G32: 0x0182AE03 | H32: lw t3, 24(t0) | I32: lw | J32: POLL | K32: 2001 | L32: FETCH|0x00000044|0x0182AE03 | M32: lw@0x00000044 | N32: =IF(E32="FETCH",IF(COUNTIF($M$6:M32,M32)=1,1,0),0) -> 0 | O32: ROM OK | P32: =IF(AND(E32="FETCH",F32="0x00000048"),C32-1,0) -> 0 | Q32: E:00000000:00010002:00000044:0182ae03
A33: 2 | B33: 0 | C33: 2 | D33: 5 | E33: FETCH | F33: 0x00000038 | G33: 0x01C2A383 | H33: lw t2, 28(t0) | I33: lw | J33: POLL | K33: 2002 | L33: FETCH|0x00000038|0x01C2A383 | M33: lw@0x00000038 | N33: =IF(E33="FETCH",IF(COUNTIF($M$6:M33,M33)=1,1,0),0) -> 1 | O33: ROM OK | P33: =IF(AND(E33="FETCH",F33="0x00000048"),C33-1,0) -> 0 | Q33: E:00000001:00010005:00000038:01c2a383
A34: 2 | B34: 0 | C34: 3 | D34: 9 | E34: FETCH | F34: 0x0000003C | G34: 0x0013F393 | H34: andi t2, t2, 1 | I34: andi | J34: POLL | K34: 2003 | L34: FETCH|0x0000003C|0x0013F393 | M34: andi@0x0000003C | N34: =IF(E34="FETCH",IF(COUNTIF($M$6:M34,M34)=1,1,0),0) -> 0 | O34: ROM OK | P34: =IF(AND(E34="FETCH",F34="0x00000048"),C34-1,0) -> 0 | Q34: E:00000002:00010009:0000003c:0013f393
A35: 2 | B35: 0 | C35: 4 | D35: 16 | E35: FETCH | F35: 0x00000040 | G35: 0xFE038CE3 | H35: beq t2, zero, 0x00000038 | I35: beq | J35: POLL | K35: 2004 | L35: FETCH|0x00000040|0xFE038CE3 | M35: beq@0x00000040 | N35: =IF(E35="FETCH",IF(COUNTIF($M$6:M35,M35)=1,1,0),0) -> 0 | O35: ROM OK | P35: =IF(AND(E35="FETCH",F35="0x00000048"),C35-1,0) -> 0 | Q35: E:00000003:00010010:00000040:fe038ce3
A36: 2 | B36: 0 | C36: 5 | D36: 20 | E36: FETCH | F36: 0x00000044 | G36: 0x0182AE03 | H36: lw t3, 24(t0) | I36: lw | J36: POLL | K36: 2005 | L36: FETCH|0x00000044|0x0182AE03 | M36: lw@0x00000044 | N36: =IF(E36="FETCH",IF(COUNTIF($M$6:M36,M36)=1,1,0),0) -> 0 | O36: ROM OK | P36: =IF(AND(E36="FETCH",F36="0x00000048"),C36-1,0) -> 0 | Q36: E:00000004:00010014:00000044:0182ae03
A37: 2 | B37: 0 | C37: 6 | D37: 24 | E37: FETCH | F37: 0x00000048 | G37: 0x05400413 | H37: addi s0, zero, 84 | I37: addi | J37: CORE | K37: 2006 | L37: FETCH|0x00000048|0x05400413 | M37: addi@0x00000048 | N37: =IF(E37="FETCH",IF(COUNTIF($M$6:M37,M37)=1,1,0),0) -> 0 | O37: ROM OK | P37: =IF(AND(E37="FETCH",F37="0x00000048"),C37-1,0) -> 5 | Q37: E:00000005:00010018:00000048:05400413
A38: 2 | B38: 0 | C38: 7 | D38: 31 | E38: FETCH | F38: 0x0000004C | G38: 0x1A8E0063 | H38: beq t3, s0, 0x000001EC | I38: beq | J38: CORE | K38: 2007 | L38: FETCH|0x0000004C|0x1A8E0063 | M38: beq@0x0000004C | N38: =IF(E38="FETCH",IF(COUNTIF($M$6:M38,M38)=1,1,0),0) -> 0 | O38: ROM OK | P38: =IF(AND(E38="FETCH",F38="0x00000048"),C38-1,0) -> 0 | Q38: E:00000006:0001001f:0000004c:1a8e0063
A39: 2 | B39: 0 | C39: 8 | D39: 35 | E39: FETCH | F39: 0x00000050 | G39: 0x04300413 | H39: addi s0, zero, 67 | I39: addi | J39: CORE | K39: 2008 | L39: FETCH|0x00000050|0x04300413 | M39: addi@0x00000050 | N39: =IF(E39="FETCH",IF(COUNTIF($M$6:M39,M39)=1,1,0),0) -> 0 | O39: ROM OK | P39: =IF(AND(E39="FETCH",F39="0x00000048"),C39-1,0) -> 0 | Q39: E:00000007:00010023:00000050:04300413
A40: 2 | B40: 0 | C40: 9 | D40: 39 | E40: FETCH | F40: 0x00000054 | G40: 0x188E0063 | H40: beq t3, s0, 0x000001D4 | I40: beq | J40: CORE | K40: 2009 | L40: FETCH|0x00000054|0x188E0063 | M40: beq@0x00000054 | N40: =IF(E40="FETCH",IF(COUNTIF($M$6:M40,M40)=1,1,0),0) -> 0 | O40: ROM OK | P40: =IF(AND(E40="FETCH",F40="0x00000048"),C40-1,0) -> 0 | Q40: E:00000008:00010027:00000054:188e0063
A41: 2 | B41: 0 | C41: 10 | D41: 43 | E41: FETCH | F41: 0x00000058 | G41: 0x03F00413 | H41: addi s0, zero, 63 | I41: addi | J41: CORE | K41: 2010 | L41: FETCH|0x00000058|0x03F00413 | M41: addi@0x00000058 | N41: =IF(E41="FETCH",IF(COUNTIF($M$6:M41,M41)=1,1,0),0) -> 0 | O41: ROM OK | P41: =IF(AND(E41="FETCH",F41="0x00000048"),C41-1,0) -> 0 | Q41: E:00000009:0001002b:00000058:03f00413
A42: 2 | B42: 0 | C42: 11 | D42: 47 | E42: FETCH | F42: 0x0000005C | G42: 0x0A8E0A63 | H42: beq t3, s0, 0x00000110 | I42: beq | J42: CORE | K42: 2011 | L42: FETCH|0x0000005C|0x0A8E0A63 | M42: beq@0x0000005C | N42: =IF(E42="FETCH",IF(COUNTIF($M$6:M42,M42)=1,1,0),0) -> 0 | O42: ROM OK | P42: =IF(AND(E42="FETCH",F42="0x00000048"),C42-1,0) -> 0 | Q42: E:0000000a:0001002f:0000005c:0a8e0a63
A43: 2 | B43: 0 | C43: 12 | D43: 51 | E43: FETCH | F43: 0x00000060 | G43: 0x03000413 | H43: addi s0, zero, 48 | I43: addi | J43: CORE | K43: 2012 | L43: FETCH|0x00000060|0x03000413 | M43: addi@0x00000060 | N43: =IF(E43="FETCH",IF(COUNTIF($M$6:M43,M43)=1,1,0),0) -> 0 | O43: ROM OK | P43: =IF(AND(E43="FETCH",F43="0x00000048"),C43-1,0) -> 0 | Q43: E:0000000b:00010033:00000060:03000413
... A50: 2 | B50: 0 | C50: 19 | D50: 78 | E50: FETCH | F50: 0x00000104 | G50: 0x0002AF83 | H50: lw t6, 0(t0) | I50: lw | J50: CORE | K50: 2019 | L50: FETCH|0x00000104|0x0002AF83 | M50: lw@0x00000104 | N50: =IF(E50="FETCH",IF(COUNTIF($M$6:M50,M50)=1,1,0),0) -> 0 | O50: ROM OK | P50: =IF(AND(E50="FETCH",F50="0x00000048"),C50-1,0) -> 0 | Q50: E:00000012:0001004e:00000104:0002af83
A51: 2 | B51: 0 | C51: 20 | D51: 81 | E51: LED_WRITE | F51: 0x20000000 | G51: 0x00000000 | H51: MMIO GPIO write | I51: LED_WRITE | J51: MMIO | K51: 2020 | L51: LED_WRITE|0x20000000|0x00000000 | N51: =IF(E51="FETCH",IF(COUNTIF($M$6:M51,M51)=1,1,0),0) -> 0 | O51: MMIO OK | P51: =IF(AND(E51="FETCH",F51="0x00000048"),C51-1,0) -> 0 | Q51: E:00000013:00020051:20000000:00000000
A52: 3 | B52: 4 | C52: 1 | D52: 5 | E52: FETCH | F52: 0x00000040 | G52: 0xFE038CE3 | H52: beq t2, zero, 0x00000038 | I52: beq | J52: POLL | K52: 3001 | L52: FETCH|0x00000040|0xFE038CE3 | M52: beq@0x00000040 | N52: =IF(E52="FETCH",IF(COUNTIF($M$6:M52,M52)=1,1,0),0) -> 0 | O52: ROM OK | P52: =IF(AND(E52="FETCH",F52="0x00000048"),C52-1,0) -> 0 | Q52: E:00000000:00010005:00000040:fe038ce3
A53: 3 | B53: 4 | C53: 2 | D53: 9 | E53: FETCH | F53: 0x00000044 | G53: 0x0182AE03 | H53: lw t3, 24(t0) | I53: lw | J53: POLL | K53: 3002 | L53: FETCH|0x00000044|0x0182AE03 | M53: lw@0x00000044 | N53: =IF(E53="FETCH",IF(COUNTIF($M$6:M53,M53)=1,1,0),0) -> 0 | O53: ROM OK | P53: =IF(AND(E53="FETCH",F53="0x00000048"),C53-1,0) -> 0 | Q53: E:00000001:00010009:00000044:0182ae03
A54: 3 | B54: 4 | C54: 3 | D54: 13 | E54: FETCH | F54: 0x00000048 | G54: 0x05400413 | H54: addi s0, zero, 84 | I54: addi | J54: CORE | K54: 3003 | L54: FETCH|0x00000048|0x05400413 | M54: addi@0x00000048 | N54: =IF(E54="FETCH",IF(COUNTIF($M$6:M54,M54)=1,1,0),0) -> 0 | O54: ROM OK | P54: =IF(AND(E54="FETCH",F54="0x00000048"),C54-1,0) -> 2 | Q54: E:00000002:0001000d:00000048:05400413
A55: 3 | B55: 4 | C55: 4 | D55: 20 | E55: FETCH | F55: 0x0000004C | G55: 0x1A8E0063 | H55: beq t3, s0, 0x000001EC | I55: beq | J55: CORE | K55: 3004 | L55: FETCH|0x0000004C|0x1A8E0063 | M55: beq@0x0000004C | N55: =IF(E55="FETCH",IF(COUNTIF($M$6:M55,M55)=1,1,0),0) -> 0 | O55: ROM OK | P55: =IF(AND(E55="FETCH",F55="0x00000048"),C55-1,0) -> 0 | Q55: E:00000003:00010014:0000004c:1a8e0063
A56: 3 | B56: 4 | C56: 5 | D56: 24 | E56: FETCH | F56: 0x00000050 | G56: 0x04300413 | H56: addi s0, zero, 67 | I56: addi | J56: CORE | K56: 3005 | L56: FETCH|0x00000050|0x04300413 | M56: addi@0x00000050 | N56: =IF(E56="FETCH",IF(COUNTIF($M$6:M56,M56)=1,1,0),0) -> 0 | O56: ROM OK | P56: =IF(AND(E56="FETCH",F56="0x00000048"),C56-1,0) -> 0 | Q56: E:00000004:00010018:00000050:04300413
A57: 3 | B57: 4 | C57: 6 | D57: 28 | E57: FETCH | F57: 0x00000054 | G57: 0x188E0063 | H57: beq t3, s0, 0x000001D4 | I57: beq | J57: CORE | K57: 3006 | L57: FETCH|0x00000054|0x188E0063 | M57: beq@0x00000054 | N57: =IF(E57="FETCH",IF(COUNTIF($M$6:M57,M57)=1,1,0),0) -> 0 | O57: ROM OK | P57: =IF(AND(E57="FETCH",F57="0x00000048"),C57-1,0) -> 0 | Q57: E:00000005:0001001c:00000054:188e0063
A58: 3 | B58: 4 | C58: 7 | D58: 32 | E58: FETCH | F58: 0x00000058 | G58: 0x03F00413 | H58: addi s0, zero, 63 | I58: addi | J58: CORE | K58: 3007 | L58: FETCH|0x00000058|0x03F00413 | M58: addi@0x00000058 | N58: =IF(E58="FETCH",IF(COUNTIF($M$6:M58,M58)=1,1,0),0) -> 0 | O58: ROM OK | P58: =IF(AND(E58="FETCH",F58="0x00000048"),C58-1,0) -> 0 | Q58: E:00000006:00010020:00000058:03f00413
A59: 3 | B59: 4 | C59: 8 | D59: 36 | E59: FETCH | F59: 0x0000005C | G59: 0x0A8E0A63 | H59: beq t3, s0, 0x00000110 | I59: beq | J59: CORE | K59: 3008 | L59: FETCH|0x0000005C|0x0A8E0A63 | M59: beq@0x0000005C | N59: =IF(E59="FETCH",IF(COUNTIF($M$6:M59,M59)=1,1,0),0) -> 0 | O59: ROM OK | P59: =IF(AND(E59="FETCH",F59="0x00000048"),C59-1,0) -> 0 | Q59: E:00000007:00010024:0000005c:0a8e0a63
...

Sheet ROM LAB03
A1: ROM LAB-03 / 256 СЛОВ
A3: 202 активных инструкционных слова + 54 хвостовых NOP • адреса и коды из SHA-проверенного lab03_boot.hex
A4: СТАРТ | B4: НАБЛЮДЕНИЕ | C4: СРАВНЕНИЕ | D4: LED / MMIO | E4: КОМАНДЫ | F4: 12 ТРАСС | G4: RAW T3 | H4: ROM | I4: ТЕРМИНЫ | J4: ПРОИСХОЖДЕНИЕ | K4: БИТЫ 202 | L4: 10 КАРТОЧЕК
A5: № ROM | B5: PC | C5: WORD | D5: Мнемоника | E5: Ассемблер | F5: Opcode (7 бит) | G5: Двоичное слово 32 бита | H5: Участок | I5: FETCH (12) | J5: Статус наблюдения
A6: 0 | B6: 0x00000000 | C6: 0x200002B7 | D6: lui | E6: lui t0, 0x20000000 | F6: 0110111 | G6: 0010 0000 0000 0000 0000 0010 1011 0111 | H6: КОД | I6: =COUNTIF('ДАННЫЕ T3'!$F$6:$F$286,B6) -> 0 | J6: =IF(I6>0,"FETCH зарегистрирован","Нет FETCH в окне") -> Нет FETCH в окне
A7: 1 | B7: 0x00000004 | C7: 0x0002A023 | D7: sw | E7: sw zero, 0(t0) | F7: 0100011 | G7: 0000 0000 0000 0010 1010 0000 0010 0011 | H7: КОД | I7: =COUNTIF('ДАННЫЕ T3'!$F$6:$F$286,B7) -> 0 | J7: =IF(I7>0,"FETCH зарегистрирован","Нет FETCH в окне") -> Нет FETCH в окне
A8: 2 | B8: 0x00000008 | C8: 0x05200313 | D8: addi | E8: addi t1, zero, 82 | F8: 0010011 | G8: 0000 0101 0010 0000 0000 0011 0001 0011 | H8: КОД | I8: =COUNTIF('ДАННЫЕ T3'!$F$6:$F$286,B8) -> 0 | J8: =IF(I8>0,"FETCH зарегистрирован","Нет FETCH в окне") -> Нет FETCH в окне
A9: 3 | B9: 0x0000000C | C9: 0x308000EF | D9: jal | E9: jal ra, 0x00000314 | F9: 1101111 | G9: 0011 0000 1000 0000 0000 0000 1110 1111 | H9: КОД | I9: =COUNTIF('ДАННЫЕ T3'!$F$6:$F$286,B9) -> 0 | J9: =IF(I9>0,"FETCH зарегистрирован","Нет FETCH в окне") -> Нет FETCH в окне
A10: 4 | B10: 0x00000010 | C10: 0x04500313 | D10: addi | E10: addi t1, zero, 69 | F10: 0010011 | G10: 0000 0100 0101 0000 0000 0011 0001 0011 | H10: КОД | I10: =COUNTIF('ДАННЫЕ T3'!$F$6:$F$286,B10) -> 0 | J10: =IF(I10>0,"FETCH зарегистрирован","Нет FETCH в окне") -> Нет FETCH в окне
A11: 5 | B11: 0x00000014 | C11: 0x300000EF | D11: jal | E11: jal ra, 0x00000314 | F11: 1101111 | G11: 0011 0000 0000 0000 0000 0000 1110 1111 | H11: КОД | I11: =COUNTIF('ДАННЫЕ T3'!$F$6:$F$286,B11) -> 0 | J11: =IF(I11>0,"FETCH зарегистрирован","Нет FETCH в окне") -> Нет FETCH в окне
A12: 6 | B12: 0x00000018 | C12: 0x04100313 | D12: addi | E12: addi t1, zero, 65 | F12: 0010011 | G12: 0000 0100 0001 0000 0000 0011 0001 0011 | H12: КОД | I12: =COUNTIF('ДАННЫЕ T3'!$F$6:$F$286,B12) -> 0 | J12: =IF(I12>0,"FETCH зарегистрирован","Нет FETCH в окне") -> Нет FETCH в окне
A13: 7 | B13: 0x0000001C | C13: 0x2F8000EF | D13: jal | E13: jal ra, 0x00000314 | F13: 1101111 | G13: 0010 1111 1000 0000 0000 0000 1110 1111 | H13: КОД | I13: =COUNTIF('ДАННЫЕ T3'!$F$6:$F$286,B13) -> 0 | J13: =IF(I13>0,"FETCH зарегистрирован","Нет FETCH в окне") -> Нет FETCH в окне
A14: 8 | B14: 0x00000020 | C14: 0x04400313 | D14: addi | E14: addi t1, zero, 68 | F14: 0010011 | G14: 0000 0100 0100 0000 0000 0011 0001 0011 | H14: КОД | I14: =COUNTIF('ДАННЫЕ T3'!$F$6:$F$286,B14) -> 0 | J14: =IF(I14>0,"FETCH зарегистрирован","Нет FETCH в окне") -> Нет FETCH в окне
A15: 9 | B15: 0x00000024 | C15: 0x2F0000EF | D15: jal | E15: jal ra, 0x00000314 | F15: 1101111 | G15: 0010 1111 0000 0000 0000 0000 1110 1111 | H15: КОД | I15: =COUNTIF('ДАННЫЕ T3'!$F$6:$F$286,B15) -> 0 | J15: =IF(I15>0,"FETCH зарегистрирован","Нет FETCH в окне") -> Нет FETCH в окне
A16: 10 | B16: 0x00000028 | C16: 0x05900313 | D16: addi | E16: addi t1, zero, 89 | F16: 0010011 | G16: 0000 0101 1001 0000 0000 0011 0001 0011 | H16: КОД | I16: =COUNTIF('ДАННЫЕ T3'!$F$6:$F$286,B16) -> 0 | J16: =IF(I16>0,"FETCH зарегистрирован","Нет FETCH в окне") -> Нет FETCH в окне
A17: 11 | B17: 0x0000002C | C17: 0x2E8000EF | D17: jal | E17: jal ra, 0x00000314 | F17: 1101111 | G17: 0010 1110 1000 0000 0000 0000 1110 1111 | H17: КОД | I17: =COUNTIF('ДАННЫЕ T3'!$F$6:$F$286,B17) -> 0 | J17: =IF(I17>0,"FETCH зарегистрирован","Нет FETCH в окне") -> Нет FETCH в окне
... A261: 255 | B261: 0x000003FC | C261: 0x00000013 | D261: nop | E261: nop | F261: 0010011 | G261: 0000 0000 0000 0000 0000 0000 0001 0011 | H261: NOP / PADDING | I261: =COUNTIF('ДАННЫЕ T3'!$F$6:$F$286,B261) -> 0 | J261: =IF(I261>0,"FETCH зарегистрирован","Нет FETCH в окне") -> Нет FETCH в окне

Sheet ЗАХВАТЫ
A1: 12 АППАРАТНЫХ ЗАХВАТОВ
A3: Серия LAB-03.3 • каждая строка связана с сырыми T3 • RAW FETCH меняется, CORE — устойчивый
A4: СТАРТ | B4: НАБЛЮДЕНИЕ | C4: СРАВНЕНИЕ | D4: LED / MMIO | E4: КОМАНДЫ | F4: 12 ТРАСС | G4: RAW T3 | H4: ROM | I4: ТЕРМИНЫ | J4: ПРОИСХОЖДЕНИЕ | K4: БИТЫ 202 | L4: 10 КАРТОЧЕК
A5: № захвата | B5: UART | C5: UTC | D5: FETCH RAW | E5: Событий | F5: LED_WRITE | G5: До PC=0x48 | H5: CORE FETCH | I5: CORE событий | J5: Проверка | K5: Raw filename | L5: SHA-256 RAW | M5: SHA ОК | O5: UART 0 | P5: UART 4
A6: 1 | B6: 4 | C6: 2026-10-20T21:46:43+00:00 | D6: =COUNTIFS('ДАННЫЕ T3'!$A$6:$A$286,A6,'ДАННЫЕ T3'!$E$6:$E$286,"FETCH") -> 25 | E6: =COUNTIF('ДАННЫЕ T3'!$A$6:$A$286,A6) -> 26 | F6: =IFERROR(INDEX('ДАННЫЕ T3'!$G$6:$G$286,MATCH(A6*1000+E6,'ДАННЫЕ T3'!$K$6:$K$286,0)),"") -> 0x00000008 | G6: =SUMIFS('ДАННЫЕ T3'!$P$6:$P$286,'ДАННЫЕ T3'!$A$6:$A$286,A6) -> 3 | H6: =D6-G6 -> 22 | I6: =E6-G6 -> 23 | J6: PASS | K6: raw/run_001_led_4.txt | L6: 60cf35d5d2ba61aeb1cd157b97139bd75db83c8adb7ca58cd3f09c99e0cfd170 | M6: OK | O6: =IF(B6="0",D6,0) -> 0 | P6: =IF(B6="4",D6,0) -> 25
A7: 2 | B7: 0 | C7: 2026-10-20T21:46:45+00:00 | D7: =COUNTIFS('ДАННЫЕ T3'!$A$6:$A$286,A7,'ДАННЫЕ T3'!$E$6:$E$286,"FETCH") -> 19 | E7: =COUNTIF('ДАННЫЕ T3'!$A$6:$A$286,A7) -> 20 | F7: =IFERROR(INDEX('ДАННЫЕ T3'!$G$6:$G$286,MATCH(A7*1000+E7,'ДАННЫЕ T3'!$K$6:$K$286,0)),"") -> 0x00000000 | G7: =SUMIFS('ДАННЫЕ T3'!$P$6:$P$286,'ДАННЫЕ T3'!$A$6:$A$286,A7) -> 5 | H7: =D7-G7 -> 14 | I7: =E7-G7 -> 15 | J7: PASS | K7: raw/run_002_led_0.txt | L7: 812d585cb3d91486edbaaee4ea773d6277be2bfac568376899e2459bf5c9888b | M7: OK | O7: =IF(B7="0",D7,0) -> 19 | P7: =IF(B7="4",D7,0) -> 0
A8: 3 | B8: 4 | C8: 2026-10-20T21:46:47+00:00 | D8: =COUNTIFS('ДАННЫЕ T3'!$A$6:$A$286,A8,'ДАННЫЕ T3'!$E$6:$E$286,"FETCH") -> 24 | E8: =COUNTIF('ДАННЫЕ T3'!$A$6:$A$286,A8) -> 25 | F8: =IFERROR(INDEX('ДАННЫЕ T3'!$G$6:$G$286,MATCH(A8*1000+E8,'ДАННЫЕ T3'!$K$6:$K$286,0)),"") -> 0x00000008 | G8: =SUMIFS('ДАННЫЕ T3'!$P$6:$P$286,'ДАННЫЕ T3'!$A$6:$A$286,A8) -> 2 | H8: =D8-G8 -> 22 | I8: =E8-G8 -> 23 | J8: PASS | K8: raw/run_003_led_4.txt | L8: ba2a4c72611cb82f8e54ee2b2bad4f725d22fc314a17c2f0a6a0efd1d497b80f | M8: OK | O8: =IF(B8="0",D8,0) -> 0 | P8: =IF(B8="4",D8,0) -> 24
A9: 4 | B9: 0 | C9: 2026-10-20T21:46:49+00:00 | D9: =COUNTIFS('ДАННЫЕ T3'!$A$6:$A$286,A9,'ДАННЫЕ T3'!$E$6:$E$286,"FETCH") -> 17 | E9: =COUNTIF('ДАННЫЕ T3'!$A$6:$A$286,A9) -> 18 | F9: =IFERROR(INDEX('ДАННЫЕ T3'!$G$6:$G$286,MATCH(A9*1000+E9,'ДАННЫЕ T3'!$K$6:$K$286,0)),"") -> 0x00000000 | G9: =SUMIFS('ДАННЫЕ T3'!$P$6:$P$286,'ДАННЫЕ T3'!$A$6:$A$286,A9) -> 3 | H9: =D9-G9 -> 14 | I9: =E9-G9 -> 15 | J9: PASS | K9: raw/run_004_led_0.txt | L9: b19aa59fa8509e8c9ebdc4817adae904b630f89a004363867fb46636eaabbb08 | M9: OK | O9: =IF(B9="0",D9,0) -> 17 | P9: =IF(B9="4",D9,0) -> 0
A10: 5 | B10: 4 | C10: 2026-10-20T21:46:50+00:00 | D10: =COUNTIFS('ДАННЫЕ T3'!$A$6:$A$286,A10,'ДАННЫЕ T3'!$E$6:$E$286,"FETCH") -> 28 | E10: =COUNTIF('ДАННЫЕ T3'!$A$6:$A$286,A10) -> 29 | F10: =IFERROR(INDEX('ДАННЫЕ T3'!$G$6:$G$286,MATCH(A10*1000+E10,'ДАННЫЕ T3'!$K$6:$K$286,0)),"") -> 0x00000008 | G10: =SUMIFS('ДАННЫЕ T3'!$P$6:$P$286,'ДАННЫЕ T3'!$A$6:$A$286,A10) -> 6 | H10: =D10-G10 -> 22 | I10: =E10-G10 -> 23 | J10: PASS | K10: raw/run_005_led_4.txt | L10: 22c15a2d9d747302c8fd4cc75b569feef8d9ad77655861ad26765a58fae6d8fa | M10: OK | O10: =IF(B10="0",D10,0) -> 0 | P10: =IF(B10="4",D10,0) -> 28
A11: 6 | B11: 0 | C11: 2026-10-20T21:46:52+00:00 | D11: =COUNTIFS('ДАННЫЕ T3'!$A$6:$A$286,A11,'ДАННЫЕ T3'!$E$6:$E$286,"FETCH") -> 18 | E11: =COUNTIF('ДАННЫЕ T3'!$A$6:$A$286,A11) -> 19 | F11: =IFERROR(INDEX('ДАННЫЕ T3'!$G$6:$G$286,MATCH(A11*1000+E11,'ДАННЫЕ T3'!$K$6:$K$286,0)),"") -> 0x00000000 | G11: =SUMIFS('ДАННЫЕ T3'!$P$6:$P$286,'ДАННЫЕ T3'!$A$6:$A$286,A11) -> 4 | H11: =D11-G11 -> 14 | I11: =E11-G11 -> 15 | J11: PASS | K11: raw/run_006_led_0.txt | L11: 57eeb8f79309060d826529ec5464776811c66be3063a17b0da692ae3fff1266a | M11: OK | O11: =IF(B11="0",D11,0) -> 18 | P11: =IF(B11="4",D11,0) -> 0
A12: 7 | B12: 4 | C12: 2026-10-20T21:46:54+00:00 | D12: =COUNTIFS('ДАННЫЕ T3'!$A$6:$A$286,A12,'ДАННЫЕ T3'!$E$6:$E$286,"FETCH") -> 27 | E12: =COUNTIF('ДАННЫЕ T3'!$A$6:$A$286,A12) -> 28 | F12: =IFERROR(INDEX('ДАННЫЕ T3'!$G$6:$G$286,MATCH(A12*1000+E12,'ДАННЫЕ T3'!$K$6:$K$286,0)),"") -> 0x00000008 | G12: =SUMIFS('ДАННЫЕ T3'!$P$6:$P$286,'ДАННЫЕ T3'!$A$6:$A$286,A12) -> 5 | H12: =D12-G12 -> 22 | I12: =E12-G12 -> 23 | J12: PASS | K12: raw/run_007_led_4.txt | L12: 65475e4357efd71b53c24425eecc3949ef3e5aa5e64b2b8f5f699cd0085fc9c3 | M12: OK | O12: =IF(B12="0",D12,0) -> 0 | P12: =IF(B12="4",D12,0) -> 27
A13: 8 | B13: 0 | C13: 2026-10-20T21:46:55+00:00 | D13: =COUNTIFS('ДАННЫЕ T3'!$A$6:$A$286,A13,'ДАННЫЕ T3'!$E$6:$E$286,"FETCH") -> 19 | E13: =COUNTIF('ДАННЫЕ T3'!$A$6:$A$286,A13) -> 20 | F13: =IFERROR(INDEX('ДАННЫЕ T3'!$G$6:$G$286,MATCH(A13*1000+E13,'ДАННЫЕ T3'!$K$6:$K$286,0)),"") -> 0x00000000 | G13: =SUMIFS('ДАННЫЕ T3'!$P$6:$P$286,'ДАННЫЕ T3'!$A$6:$A$286,A13) -> 5 | H13: =D13-G13 -> 14 | I13: =E13-G13 -> 15 | J13: PASS | K13: raw/run_008_led_0.txt | L13: 9b4786d1db456ec104b6964556c24a02f906711fca9711d68447ca2190594f2e | M13: OK | O13: =IF(B13="0",D13,0) -> 19 | P13: =IF(B13="4",D13,0) -> 0
A14: 9 | B14: 4 | C14: 2026-10-20T21:46:57+00:00 | D14: =COUNTIFS('ДАННЫЕ T3'!$A$6:$A$286,A14,'ДАННЫЕ T3'!$E$6:$E$286,"FETCH") -> 25 | E14: =COUNTIF('ДАННЫЕ T3'!$A$6:$A$286,A14) -> 26 | F14: =IFERROR(INDEX('ДАННЫЕ T3'!$G$6:$G$286,MATCH(A14*1000+E14,'ДАННЫЕ T3'!$K$6:$K$286,0)),"") -> 0x00000008 | G14: =SUMIFS('ДАННЫЕ T3'!$P$6:$P$286,'ДАННЫЕ T3'!$A$6:$A$286,A14) -> 3 | H14: =D14-G14 -> 22 | I14: =E14-G14 -> 23 | J14: PASS | K14: raw/run_009_led_4.txt | L14: 60cf35d5d2ba61aeb1cd157b97139bd75db83c8adb7ca58cd3f09c99e0cfd170 | M14: OK | O14: =IF(B14="0",D14,0) -> 0 | P14: =IF(B14="4",D14,0) -> 25
A15: 10 | B15: 0 | C15: 2026-10-20T21:46:59+00:00 | D15: =COUNTIFS('ДАННЫЕ T3'!$A$6:$A$286,A15,'ДАННЫЕ T3'!$E$6:$E$286,"FETCH") -> 20 | E15: =COUNTIF('ДАННЫЕ T3'!$A$6:$A$286,A15) -> 21 | F15: =IFERROR(INDEX('ДАННЫЕ T3'!$G$6:$G$286,MATCH(A15*1000+E15,'ДАННЫЕ T3'!$K$6:$K$286,0)),"") -> 0x00000000 | G15: =SUMIFS('ДАННЫЕ T3'!$P$6:$P$286,'ДАННЫЕ T3'!$A$6:$A$286,A15) -> 6 | H15: =D15-G15 -> 14 | I15: =E15-G15 -> 15 | J15: PASS | K15: raw/run_010_led_0.txt | L15: 359552701dd6001a18fa0669d801474aa58d51799f947ac5fa098c0c9657cea8 | M15: OK | O15: =IF(B15="0",D15,0) -> 20 | P15: =IF(B15="4",D15,0) -> 0
A16: 11 | B16: 4 | C16: 2026-10-20T21:47:00+00:00 | D16: =COUNTIFS('ДАННЫЕ T3'!$A$6:$A$286,A16,'ДАННЫЕ T3'!$E$6:$E$286,"FETCH") -> 27 | E16: =COUNTIF('ДАННЫЕ T3'!$A$6:$A$286,A16) -> 28 | F16: =IFERROR(INDEX('ДАННЫЕ T3'!$G$6:$G$286,MATCH(A16*1000+E16,'ДАННЫЕ T3'!$K$6:$K$286,0)),"") -> 0x00000008 | G16: =SUMIFS('ДАННЫЕ T3'!$P$6:$P$286,'ДАННЫЕ T3'!$A$6:$A$286,A16) -> 5 | H16: =D16-G16 -> 22 | I16: =E16-G16 -> 23 | J16: PASS | K16: raw/run_011_led_4.txt | L16: 65475e4357efd71b53c24425eecc3949ef3e5aa5e64b2b8f5f699cd0085fc9c3 | M16: OK | O16: =IF(B16="0",D16,0) -> 0 | P16: =IF(B16="4",D16,0) -> 27
A17: 12 | B17: 0 | C17: 2026-10-20T21:47:02+00:00 | D17: =COUNTIFS('ДАННЫЕ T3'!$A$6:$A$286,A17,'ДАННЫЕ T3'!$E$6:$E$286,"FETCH") -> 20 | E17: =COUNTIF('ДАННЫЕ T3'!$A$6:$A$286,A17) -> 21 | F17: =IFERROR(INDEX('ДАННЫЕ T3'!$G$6:$G$286,MATCH(A17*1000+E17,'ДАННЫЕ T3'!$K$6:$K$286,0)),"") -> 0x00000000 | G17: =SUMIFS('ДАННЫЕ T3'!$P$6:$P$286,'ДАННЫЕ T3'!$A$6:$A$286,A17) -> 6 | H17: =D17-G17 -> 14 | I17: =E17-G17 -> 15 | J17: PASS | K17: raw/run_012_led_0.txt | L17: 6bd27554aad6ff5355dcc97386ac644450566434557e47c4277a2ea41c7c8734 | M17: OK | O17: =IF(B17="0",D17,0) -> 20 | P17: =IF(B17="4",D17,0) -> 0
A19: СРАВНЕНИЕ ПОВТОРЯЕМОСТИ: ЧИСЛО RAW FETCH
B42: Отличие полного количества FETCH объясняется вариацией префикса UART polling. Для корректного сопоставления используйте сравнение от единственного PC=0x00000048 до LED_WRITE. Не приравнивайте циклы разных захватов.

Sheet КОМАНДЫ
A1: КОМАНДЫ RV32I / ТОЛЬКО НАШИ ДАННЫЕ
A3: 6 мнемоник реально встречаются в FETCH • ещё 4 присутствуют в ROM • NOP только хвостовое заполнение
A4: СТАРТ | B4: НАБЛЮДЕНИЕ | C4: СРАВНЕНИЕ | D4: LED / MMIO | E4: КОМАНДЫ | F4: 12 ТРАСС | G4: RAW T3 | H4: ROM | I4: ТЕРМИНЫ | J4: ПРОИСХОЖДЕНИЕ | K4: БИТЫ 202 | L4: 10 КАРТОЧЕК
A6: Команда | B6: English | C6: Формат | D6: Синтаксис | E6: Действие ISA | F6: Роль в LAB-03 | G6: FETCH всего | H6: Разных PC | I6: ROM слов | J6: Пример PC | K6: Машинное слово | L6: Дизассемблирование | M6: Наблюдение | N6: Граница вывода
A7: addi | B7: Add Immediate | C7: I | D7: addi rd, rs1, imm | E7: rd ← rs1 + sign_extend(imm) | F7: Задаёт ASCII-коды команд, маски и небольшие константы. | G7: =COUNTIF('ДАННЫЕ T3'!$I$6:$I$286,A7) -> 108 | H7: =SUMIF('ДАННЫЕ T3'!$I$6:$I$286,A7,'ДАННЫЕ T3'!$N$6:$N$286) -> 13 | I7: =COUNTIF('ROM LAB03'!$D$6:$D$261,A7) -> 78 | J7: 0x00000048 | K7: 0x05400413 | L7: addi s0, zero, 84 | M7: =IF(G7>0,"FETCH Наблюдался",IF(A7="nop","NOP/PADDING","ТОЛЬКО ROM")) -> FETCH Наблюдался | N7: FETCH ≠ retirement
A8: andi | B8: AND Immediate | C8: I | D8: andi rd, rs1, imm | E8: rd ← rs1 AND sign_extend(imm) | F8: PC 0x03C: оставляет бит готовности UART_RX_STATUS. | G8: =COUNTIF('ДАННЫЕ T3'!$I$6:$I$286,A8) -> 11 | H8: =SUMIF('ДАННЫЕ T3'!$I$6:$I$286,A8,'ДАННЫЕ T3'!$N$6:$N$286) -> 1 | I8: =COUNTIF('ROM LAB03'!$D$6:$D$261,A8) -> 4 | J8: 0x0000003C | K8: 0x0013F393 | L8: andi t2, t2, 1 | M8: =IF(G8>0,"FETCH Наблюдался",IF(A8="nop","NOP/PADDING","ТОЛЬКО ROM")) -> FETCH Наблюдался | N8: FETCH ≠ retirement
A9: beq | B9: Branch if Equal | C9: B | D9: beq rs1, rs2, target | E9: Если rs1=rs2, переход к target | F9: PC 0x040: возврат к polling при отсутствии байта. | G9: =COUNTIF('ДАННЫЕ T3'!$I$6:$I$286,A9) -> 87 | H9: =SUMIF('ДАННЫЕ T3'!$I$6:$I$286,A9,'ДАННЫЕ T3'!$N$6:$N$286) -> 9 | I9: =COUNTIF('ROM LAB03'!$D$6:$D$261,A9) -> 23 | J9: 0x00000040 | K9: 0xFE038CE3 | L9: beq t2, zero, 0x00000038 | M9: =IF(G9>0,"FETCH Наблюдался",IF(A9="nop","NOP/PADDING","ТОЛЬКО ROM")) -> FETCH Наблюдался | N9: FETCH ≠ retirement
A10: jal | B10: Jump And Link | C10: J | D10: jal rd, target | E10: rd ← PC+4; PC ← target | F10: Переход к общей процедуре apply. | G10: =COUNTIF('ДАННЫЕ T3'!$I$6:$I$286,A10) -> 12 | H10: =SUMIF('ДАННЫЕ T3'!$I$6:$I$286,A10,'ДАННЫЕ T3'!$N$6:$N$286) -> 2 | I10: =COUNTIF('ROM LAB03'!$D$6:$D$261,A10) -> 68 | J10: 0x000000B4 | K10: 0x04C0006F | L10: jal zero, 0x00000100 | M10: =IF(G10>0,"FETCH Наблюдался",IF(A10="nop","NOP/PADDING","ТОЛЬКО ROM")) -> FETCH Наблюдался | N10: FETCH ≠ retirement
A11: lw | B11: Load Word | C11: I | D11: lw rd, offset(rs1) | E11: rd ← MEM32[rs1 + offset] | F11: Читает UART-статус и код команды; после sw — readback LED. | G11: =COUNTIF('ДАННЫЕ T3'!$I$6:$I$286,A11) -> 39 | H11: =SUMIF('ДАННЫЕ T3'!$I$6:$I$286,A11,'ДАННЫЕ T3'!$N$6:$N$286) -> 3 | I11: =COUNTIF('ROM LAB03'!$D$6:$D$261,A11) -> 10 | J11: 0x00000104 | K11: 0x0002AF83 | L11: lw t6, 0(t0) | M11: =IF(G11>0,"FETCH Наблюдался",IF(A11="nop","NOP/PADDING","ТОЛЬКО ROM")) -> FETCH Наблюдался | N11: FETCH ≠ retirement
A12: sw | B12: Store Word | C12: S | D12: sw rs2, offset(rs1) | E12: MEM32[rs1 + offset] ← rs2 | F12: PC 0x100: инструкция записи LED-регистра через MMIO. | G12: =COUNTIF('ДАННЫЕ T3'!$I$6:$I$286,A12) -> 12 | H12: =SUMIF('ДАННЫЕ T3'!$I$6:$I$286,A12,'ДАННЫЕ T3'!$N$6:$N$286) -> 1 | I12: =COUNTIF('ROM LAB03'!$D$6:$D$261,A12) -> 5 | J12: 0x00000100 | K12: 0x01D2A023 | L12: sw t4, 0(t0) | M12: =IF(G12>0,"FETCH Наблюдался",IF(A12="nop","NOP/PADDING","ТОЛЬКО ROM")) -> FETCH Наблюдался | N12: FETCH ≠ retirement
A13: lui | B13: Load Upper Immediate | C13: U | D13: lui rd, imm20 | E13: rd ← imm20 << 12 | F13: PC 0x000: формирует t0=0x20000000. | G13: =COUNTIF('ДАННЫЕ T3'!$I$6:$I$286,A13) -> 0 | H13: =SUMIF('ДАННЫЕ T3'!$I$6:$I$286,A13,'ДАННЫЕ T3'!$N$6:$N$286) -> 0 | I13: =COUNTIF('ROM LAB03'!$D$6:$D$261,A13) -> 1 | J13: 0x00000000 | K13: 0x200002B7 | L13: lui t0, 0x20000000 | M13: =IF(G13>0,"FETCH Наблюдался",IF(A13="nop","NOP/PADDING","ТОЛЬКО ROM")) -> ТОЛЬКО ROM | N13: В 12 трассах нет FETCH
A14: bne | B14: Branch if Not Equal | C14: B | D14: bne rs1, rs2, target | E14: Если rs1≠rs2, переход к target | F14: PC 0x108: сверка readback с записанной маской. | G14: =COUNTIF('ДАННЫЕ T3'!$I$6:$I$286,A14) -> 0 | H14: =SUMIF('ДАННЫЕ T3'!$I$6:$I$286,A14,'ДАННЫЕ T3'!$N$6:$N$286) -> 0 | I14: =COUNTIF('ROM LAB03'!$D$6:$D$261,A14) -> 1 | J14: 0x00000108 | K14: 0x0BDF9C63 | L14: bne t6, t4, 0x000001C0 | M14: =IF(G14>0,"FETCH Наблюдался",IF(A14="nop","NOP/PADDING","ТОЛЬКО ROM")) -> ТОЛЬКО ROM | N14: В 12 трассах нет FETCH
A15: srli | B15: Shift Right Logical Immediate | C15: I | D15: srli rd, rs1, shamt | E15: rd ← unsigned(rs1) >> shamt | F15: Печать T3: получение шестнадцатеричных цифр. | G15: =COUNTIF('ДАННЫЕ T3'!$I$6:$I$286,A15) -> 0 | H15: =SUMIF('ДАННЫЕ T3'!$I$6:$I$286,A15,'ДАННЫЕ T3'!$N$6:$N$286) -> 0 | I15: =COUNTIF('ROM LAB03'!$D$6:$D$261,A15) -> 8 | J15: 0x000002A4 | K15: 0x01C55313 | L15: srli t1, a0, 28 | M15: =IF(G15>0,"FETCH Наблюдался",IF(A15="nop","NOP/PADDING","ТОЛЬКО ROM")) -> ТОЛЬКО ROM | N15: В 12 трассах нет FETCH
A16: jalr | B16: Jump And Link Register | C16: I | D16: jalr rd, offset(rs1) | E16: rd ← PC+4; PC ← (rs1+offset) & ~1 | F16: Возвраты из функций UART-печати. | G16: =COUNTIF('ДАННЫЕ T3'!$I$6:$I$286,A16) -> 0 | H16: =SUMIF('ДАННЫЕ T3'!$I$6:$I$286,A16,'ДАННЫЕ T3'!$N$6:$N$286) -> 0 | I16: =COUNTIF('ROM LAB03'!$D$6:$D$261,A16) -> 4 | J16: 0x000002E4 | K16: 0x000B8067 | L16: jalr zero, 0(s7) | M16: =IF(G16>0,"FETCH Наблюдался",IF(A16="nop","NOP/PADDING","ТОЛЬКО ROM")) -> ТОЛЬКО ROM | N16: В 12 трассах нет FETCH
A17: nop | B17: No Operation | C17: I | D17: nop (addi zero, zero, 0) | E17: Не изменяет архитектурного состояния | F17: 54 слова заполнения ROM, не наблюдаются в трассах. | G17: =COUNTIF('ДАННЫЕ T3'!$I$6:$I$286,A17) -> 0 | H17: =SUMIF('ДАННЫЕ T3'!$I$6:$I$286,A17,'ДАННЫЕ T3'!$N$6:$N$286) -> 0 | I17: =COUNTIF('ROM LAB03'!$D$6:$D$261,A17) -> 54 | J17: 0x00000328 | K17: 0x00000013 | L17: nop | M17: =IF(G17>0,"FETCH Наблюдался",IF(A17="nop","NOP/PADDING","ТОЛЬКО ROM")) -> NOP/PADDING | N17: В 12 трассах нет FETCH
A19: Сведения о назначении команд — по исходному коду LAB-03 и зафиксированной ROM. Числа FETCH вычисляются из листа «ДАННЫЕ T3». Команды только из ROM не объявляются аппаратно выполненными.

Sheet КАТАЛОГ БИТОВ
A1: LAB-03 / МАШИННЫЕ КОМАНДЫ — 202 РАЗБОРА
A3: Все 202 слова действующей прошивки (ROM 0x000…0x324). Только 29 PC наблюдались в серии 12 T3. 54 хвостовых NOP — заполнение, не активная программа.
A4: СТАРТ | B4: НАБЛЮДЕНИЕ | C4: СРАВНЕНИЕ | D4: LED / MMIO | E4: КОМАНДЫ | F4: 12 ТРАСС | G4: RAW T3 | H4: ROM | I4: ТЕРМИНЫ | J4: ПРОИСХОЖДЕНИЕ | K4: БИТЫ 202 | L4: 10 КАРТОЧЕК
B6: Каталог: каждый адрес PC, машинное слово, инструкция, тип кодирования и поля [31:0] из неизменной LAB-03 ROM.
A8: № | B8: PC | C8: WORD | D8: RV32I ASM | E8: Команда | F8: Формат | G8: FETCH (12) | H8: imm, dec | I8: Target | J8: Binary [31:0] | K8: Действие / замечание | L8: Статус | M8: Поле 1 · биты / значение / имя | N8: Поле 2 · биты / значение / имя | O8: Поле 3 · биты / значение / имя | P8: Поле 4 · биты / значение / имя | Q8: Поле 5 · биты / значение / имя | R8: Поле 6 · биты / значение / имя | S8: Поле 7 · биты / значение / имя | T8: Поле 8 · биты / значение / имя
A9: 1 | B9: 0x00000000 | C9: 0x200002B7 | D9: lui t0, 0x20000000 | E9: lui | F9: U | G9: 0 | H9: 131072 | I9: — | J9: 00100000000000000000001010110111 | K9: rd (t0) ← 0x20000000. Здесь формируется старшая часть адреса периферии. | L9: Только ROM | M9: 31–12 00100000000000000000 imm[31:12] | N9: 11–7 00101 rd | O9: 6–0 0110111 opcode
A10: 2 | B10: 0x00000004 | C10: 0x0002A023 | D10: sw zero, 0(t0) | E10: sw | F10: S | G10: 0 | H10: 0 | I10: — | J10: 00000000000000101010000000100011 | K10: MEM32[t0 +0] ← zero. Число, находящееся в rs2, не кодируется в самой инструкции. | L10: Только ROM | M10: 31–25 0000000 imm[11:5] | N10: 24–20 00000 rs2 | O10: 19–15 00101 rs1 | P10: 14–12 010 funct3 | Q10: 11–7 00000 imm[4:0] | R10: 6–0 0100011 opcode
A11: 3 | B11: 0x00000008 | C11: 0x05200313 | D11: addi t1, zero, 82 | E11: addi | F11: I | G11: 0 | H11: 82 | I11: — | J11: 00000101001000000000001100010011 | K11: t1 ← zero + (+82); арифметика RV32I по модулю 2³². | L11: Только ROM | M11: 31–20 000001010010 imm[11:0] | N11: 19–15 00000 rs1 | O11: 14–12 000 funct3 | P11: 11–7 00110 rd | Q11: 6–0 0010011 opcode
A12: 4 | B12: 0x0000000C | C12: 0x308000EF | D12: jal ra, 0x00000314 | E12: jal | F12: J | G12: 0 | H12: 776 | I12: 0x00000314 | J12: 00110000100000000000000011101111 | K12: PC ← 0x00000314; rd (ra) ← PC+4. Смещение +776 байт относительно PC. | L12: Только ROM | M12: 31 0 imm[20] | N12: 30–21 0110000100 imm[10:1] | O12: 20 0 imm[11] | P12: 19–12 00000000 imm[19:12] | Q12: 11–7 00001 rd | R12: 6–0 1101111 opcode
A13: 5 | B13: 0x00000010 | C13: 0x04500313 | D13: addi t1, zero, 69 | E13: addi | F13: I | G13: 0 | H13: 69 | I13: — | J13: 00000100010100000000001100010011 | K13: t1 ← zero + (+69); арифметика RV32I по модулю 2³². | L13: Только ROM | M13: 31–20 000001000101 imm[11:0] | N13: 19–15 00000 rs1 | O13: 14–12 000 funct3 | P13: 11–7 00110 rd | Q13: 6–0 0010011 opcode
A14: 6 | B14: 0x00000014 | C14: 0x300000EF | D14: jal ra, 0x00000314 | E14: jal | F14: J | G14: 0 | H14: 768 | I14: 0x00000314 | J14: 00110000000000000000000011101111 | K14: PC ← 0x00000314; rd (ra) ← PC+4. Смещение +768 байт относительно PC. | L14: Только ROM | M14: 31 0 imm[20] | N14: 30–21 0110000000 imm[10:1] | O14: 20 0 imm[11] | P14: 19–12 00000000 imm[19:12] | Q14: 11–7 00001 rd | R14: 6–0 1101111 opcode
A15: 7 | B15: 0x00000018 | C15: 0x04100313 | D15: addi t1, zero, 65 | E15: addi | F15: I | G15: 0 | H15: 65 | I15: — | J15: 00000100000100000000001100010011 | K15: t1 ← zero + (+65); арифметика RV32I по модулю 2³². | L15: Только ROM | M15: 31–20 000001000001 imm[11:0] | N15: 19–15 00000 rs1 | O15: 14–12 000 funct3 | P15: 11–7 00110 rd | Q15: 6–0 0010011 opcode
A16: 8 | B16: 0x0000001C | C16: 0x2F8000EF | D16: jal ra, 0x00000314 | E16: jal | F16: J | G16: 0 | H16: 760 | I16: 0x00000314 | J16: 00101111100000000000000011101111 | K16: PC ← 0x00000314; rd (ra) ← PC+4. Смещение +760 байт относительно PC. | L16: Только ROM | M16: 31 0 imm[20] | N16: 30–21 0101111100 imm[10:1] | O16: 20 0 imm[11] | P16: 19–12 00000000 imm[19:12] | Q16: 11–7 00001 rd | R16: 6–0 1101111 opcode
A17: 9 | B17: 0x00000020 | C17: 0x04400313 | D17: addi t1, zero, 68 | E17: addi | F17: I | G17: 0 | H17: 68 | I17: — | J17: 00000100010000000000001100010011 | K17: t1 ← zero + (+68); арифметика RV32I по модулю 2³². | L17: Только ROM | M17: 31–20 000001000100 imm[11:0] | N17: 19–15 00000 rs1 | O17: 14–12 000 funct3 | P17: 11–7 00110 rd | Q17: 6–0 0010011 opcode
A18: 10 | B18: 0x00000024 | C18: 0x2F0000EF | D18: jal ra, 0x00000314 | E18: jal | F18: J | G18: 0 | H18: 752 | I18: 0x00000314 | J18: 00101111000000000000000011101111 | K18: PC ← 0x00000314; rd (ra) ← PC+4. Смещение +752 байт относительно PC. | L18: Только ROM | M18: 31 0 imm[20] | N18: 30–21 0101111000 imm[10:1] | O18: 20 0 imm[11] | P18: 19–12 00000000 imm[19:12] | Q18: 11–7 00001 rd | R18: 6–0 1101111 opcode
A19: 11 | B19: 0x00000028 | C19: 0x05900313 | D19: addi t1, zero, 89 | E19: addi | F19: I | G19: 0 | H19: 89 | I19: — | J19: 00000101100100000000001100010011 | K19: t1 ← zero + (+89); арифметика RV32I по модулю 2³². | L19: Только ROM | M19: 31–20 000001011001 imm[11:0] | N19: 19–15 00000 rs1 | O19: 14–12 000 funct3 | P19: 11–7 00110 rd | Q19: 6–0 0010011 opcode
A20: 12 | B20: 0x0000002C | C20: 0x2E8000EF | D20: jal ra, 0x00000314 | E20: jal | F20: J | G20: 0 | H20: 744 | I20: 0x00000314 | J20: 00101110100000000000000011101111 | K20: PC ← 0x00000314; rd (ra) ← PC+4. Смещение +744 байт относительно PC. | L20: Только ROM | M20: 31 0 imm[20] | N20: 30–21 0101110100 imm[10:1] | O20: 20 0 imm[11] | P20: 19–12 00000000 imm[19:12] | Q20: 11–7 00001 rd | R20: 6–0 1101111 opcode
A21: 13 | B21: 0x00000030 | C21: 0x00A00313 | D21: addi t1, zero, 10 | E21: addi | F21: I | G21: 0 | H21: 10 | I21: — | J21: 00000000101000000000001100010011 | K21: t1 ← zero + (+10); арифметика RV32I по модулю 2³². | L21: Только ROM | M21: 31–20 000000001010 imm[11:0] | N21: 19–15 00000 rs1 | O21: 14–12 000 funct3 | P21: 11–7 00110 rd | Q21: 6–0 0010011 opcode
A22: 14 | B22: 0x00000034 | C22: 0x2E0000EF | D22: jal ra, 0x00000314 | E22: jal | F22: J | G22: 0 | H22: 736 | I22: 0x00000314 | J22: 00101110000000000000000011101111 | K22: PC ← 0x00000314; rd (ra) ← PC+4. Смещение +736 байт относительно PC. | L22: Только ROM | M22: 31 0 imm[20] | N22: 30–21 0101110000 imm[10:1] | O22: 20 0 imm[11] | P22: 19–12 00000000 imm[19:12] | Q22: 11–7 00001 rd | R22: 6–0 1101111 opcode
A23: 15 | B23: 0x00000038 | C23: 0x01C2A383 | D23: lw t2, 28(t0) | E23: lw | F23: I | G23: 8 | H23: 28 | I23: — | J23: 00000001110000101010001110000011 | K23: t2 ← MEM32[t0 +28]. FETCH этой инструкции не удостоверяет регистрацию DATA_READ. | L23: FETCH был | M23: 31–20 000000011100 imm[11:0] | N23: 19–15 00101 rs1 | O23: 14–12 010 funct3 | P23: 11–7 00111 rd | Q23: 6–0 0000011 opcode
A24: 16 | B24: 0x0000003C | C24: 0x0013F393 | D24: andi t2, t2, 1 | E24: andi | F24: I | G24: 11 | H24: 1 | I24: — | J24: 00000000000100111111001110010011 | K24: t2 ← t2 AND (+1); побитовое И с sign_extend(imm). | L24: FETCH был | M24: 31–20 000000000001 imm[11:0] | N24: 19–15 00111 rs1 | O24: 14–12 111 funct3 | P24: 11–7 00111 rd | Q24: 6–0 0010011 opcode
A25: 17 | B25: 0x00000040 | C25: 0xFE038CE3 | D25: beq t2, zero, 0x00000038 | E25: beq | F25: B | G25: 15 | H25: -8 | I25: 0x00000038 | J25: 11111110000000111000110011100011 | K25: Если t2 = zero, PC ← 0x00000038; иначе PC ← PC+4. Смещение -8 байт. | L25: FETCH был | M25: 31 1 imm[12] | N25: 30–25 111111 imm[10:5] | O25: 24–20 00000 rs2 | P25: 19–15 00111 rs1 | Q25: 14–12 000 funct3 | R25: 11–8 1100 imm[4:1] | S25: 7 1 imm[11] | T25: 6–0 1100011 opcode
A26: 18 | B26: 0x00000044 | C26: 0x0182AE03 | D26: lw t3, 24(t0) | E26: lw | F26: I | G26: 19 | H26: 24 | I26: — | J26: 00000001100000101010111000000011 | K26: t3 ← MEM32[t0 +24]. FETCH этой инструкции не удостоверяет регистрацию DATA_READ. | L26: FETCH был | M26: 31–20 000000011000 imm[11:0] | N26: 19–15 00101 rs1 | O26: 14–12 010 funct3 | P26: 11–7 11100 rd | Q26: 6–0 0000011 opcode
A27: 19 | B27: 0x00000048 | C27: 0x05400413 | D27: addi s0, zero, 84 | E27: addi | F27: I | G27: 12 | H27: 84 | I27: — | J27: 00000101010000000000010000010011 | K27: s0 ← zero + (+84); арифметика RV32I по модулю 2³². | L27: FETCH был | M27: 31–20 000001010100 imm[11:0] | N27: 19–15 00000 rs1 | O27: 14–12 000 funct3 | P27: 11–7 01000 rd | Q27: 6–0 0010011 opcode
A28: 20 | B28: 0x0000004C | C28: 0x1A8E0063 | D28: beq t3, s0, 0x000001ec | E28: beq | F28: B | G28: 12 | H28: 416 | I28: 0x000001EC | J28: 00011010100011100000000001100011 | K28: Если t3 = s0, PC ← 0x000001EC; иначе PC ← PC+4. Смещение +416 байт. | L28: FETCH был | M28: 31 0 imm[12] | N28: 30–25 001101 imm[10:5] | O28: 24–20 01000 rs2 | P28: 19–15 11100 rs1 | Q28: 14–12 000 funct3 | R28: 11–8 0000 imm[4:1] | S28: 7 0 imm[11] | T28: 6–0 1100011 opcode
A29: 21 | B29: 0x00000050 | C29: 0x04300413 | D29: addi s0, zero, 67 | E29: addi | F29: I | G29: 12 | H29: 67 | I29: — | J29: 00000100001100000000010000010011 | K29: s0 ← zero + (+67); арифметика RV32I по модулю 2³². | L29: FETCH был | M29: 31–20 000001000011 imm[11:0] | N29: 19–15 00000 rs1 | O29: 14–12 000 funct3 | P29: 11–7 01000 rd | Q29: 6–0 0010011 opcode
A30: 22 | B30: 0x00000054 | C30: 0x188E0063 | D30: beq t3, s0, 0x000001d4 | E30: beq | F30: B | G30: 12 | H30: 384 | I30: 0x000001D4 | J30: 00011000100011100000000001100011 | K30: Если t3 = s0, PC ← 0x000001D4; иначе PC ← PC+4. Смещение +384 байт. | L30: FETCH был | M30: 31 0 imm[12] | N30: 30–25 001100 imm[10:5] | O30: 24–20 01000 rs2 | P30: 19–15 11100 rs1 | Q30: 14–12 000 funct3 | R30: 11–8 0000 imm[4:1] | S30: 7 0 imm[11] | T30: 6–0 1100011 opcode
A31: 23 | B31: 0x00000058 | C31: 0x03F00413 | D31: addi s0, zero, 63 | E31: addi | F31: I | G31: 12 | H31: 63 | I31: — | J31: 00000011111100000000010000010011 | K31: s0 ← zero + (+63); арифметика RV32I по модулю 2³². | L31: FETCH был | M31: 31–20 000000111111 imm[11:0] | N31: 19–15 00000 rs1 | O31: 14–12 000 funct3 | P31: 11–7 01000 rd | Q31: 6–0 0010011 opcode
A32: 24 | B32: 0x0000005C | C32: 0x0A8E0A63 | D32: beq t3, s0, 0x00000110 | E32: beq | F32: B | G32: 12 | H32: 180 | I32: 0x00000110 | J32: 00001010100011100000101001100011 | K32: Если t3 = s0, PC ← 0x00000110; иначе PC ← PC+4. Смещение +180 байт. | L32: FETCH был | M32: 31 0 imm[12] | N32: 30–25 000101 imm[10:5] | O32: 24–20 01000 rs2 | P32: 19–15 11100 rs1 | Q32: 14–12 000 funct3 | R32: 11–8 1010 imm[4:1] | S32: 7 0 imm[11] | T32: 6–0 1100011 opcode
A33: 25 | B33: 0x00000060 | C33: 0x03000413 | D33: addi s0, zero, 48 | E33: addi | F33: I | G33: 12 | H33: 48 | I33: — | J33: 00000011000000000000010000010011 | K33: s0 ← zero + (+48); арифметика RV32I по модулю 2³². | L33: FETCH был | M33: 31–20 000000110000 imm[11:0] | N33: 19–15 00000 rs1 | O33: 14–12 000 funct3 | P33: 11–7 01000 rd | Q33: 6–0 0010011 opcode
A34: 26 | B34: 0x00000064 | C34: 0x048E0463 | D34: beq t3, s0, 0x000000ac | E34: beq | F34: B | G34: 12 | H34: 72 | I34: 0x000000AC | J34: 00000100100011100000010001100011 | K34: Если t3 = s0, PC ← 0x000000AC; иначе PC ← PC+4. Смещение +72 байт. | L34: FETCH был | M34: 31 0 imm[12] | N34: 30–25 000010 imm[10:5] | O34: 24–20 01000 rs2 | P34: 19–15 11100 rs1 | Q34: 14–12 000 funct3 | R34: 11–8 0100 imm[4:1] | S34: 7 0 imm[11] | T34: 6–0 1100011 opcode
A35: 27 | B35: 0x00000068 | C35: 0x03100413 | D35: addi s0, zero, 49 | E35: addi | F35: I | G35: 12 | H35: 49 | I35: — | J35: 00000011000100000000010000010011 | K35: s0 ← zero + (+49); арифметика RV32I по модулю 2³². | L35: FETCH был | M35: 31–20 000000110001 imm[11:0] | N35: 19–15 00000 rs1 | O35: 14–12 000 funct3 | P35: 11–7 01000 rd | Q35: 6–0 0010011 opcode
A36: 28 | B36: 0x0000006C | C36: 0x048E0663 | D36: beq t3, s0, 0x000000b8 | E36: beq | F36: B | G36: 6 | H36: 76 | I36: 0x000000B8 | J36: 00000100100011100000011001100011 | K36: Если t3 = s0, PC ← 0x000000B8; иначе PC ← PC+4. Смещение +76 байт. | L36: FETCH был | M36: 31 0 imm[12] | N36: 30–25 000010 imm[10:5] | O36: 24–20 01000 rs2 | P36: 19–15 11100 rs1 | Q36: 14–12 000 funct3 | R36: 11–8 0110 imm[4:1] | S36: 7 0 imm[11] | T36: 6–0 1100011 opcode
A37: 29 | B37: 0x00000070 | C37: 0x03200413 | D37: addi s0, zero, 50 | E37: addi | F37: I | G37: 6 | H37: 50 | I37: — | J37: 00000011001000000000010000010011 | K37: s0 ← zero + (+50); арифметика RV32I по модулю 2³². | L37: FETCH был | M37: 31–20 000000110010 imm[11:0] | N37: 19–15 00000 rs1 | O37: 14–12 000 funct3 | P37: 11–7 01000 rd | Q37: 6–0 0010011 opcode
A38: 30 | B38: 0x00000074 | C38: 0x048E0863 | D38: beq t3, s0, 0x000000c4 | E38: beq | F38: B | G38: 6 | H38: 80 | I38: 0x000000C4 | J38: 00000100100011100000100001100011 | K38: Если t3 = s0, PC ← 0x000000C4; иначе PC ← PC+4. Смещение +80 байт. | L38: FETCH был | M38: 31 0 imm[12] | N38: 30–25 000010 imm[10:5] | O38: 24–20 01000 rs2 | P38: 19–15 11100 rs1 | Q38: 14–12 000 funct3 | R38: 11–8 1000 imm[4:1] | S38: 7 0 imm[11] | T38: 6–0 1100011 opcode
A39: 31 | B39: 0x00000078 | C39: 0x03300413 | D39: addi s0, zero, 51 | E39: addi | F39: I | G39: 6 | H39: 51 | I39: — | J39: 00000011001100000000010000010011 | K39: s0 ← zero + (+51); арифметика RV32I по модулю 2³². | L39: FETCH был | M39: 31–20 000000110011 imm[11:0] | N39: 19–15 00000 rs1 | O39: 14–12 000 funct3 | P39: 11–7 01000 rd | Q39: 6–0 0010011 opcode
A40: 32 | B40: 0x0000007C | C40: 0x048E0A63 | D40: beq t3, s0, 0x000000d0 | E40: beq | F40: B | G40: 6 | H40: 84 | I40: 0x000000D0 | J40: 00000100100011100000101001100011 | K40: Если t3 = s0, PC ← 0x000000D0; иначе PC ← PC+4. Смещение +84 байт. | L40: FETCH был | M40: 31 0 imm[12] | N40: 30–25 000010 imm[10:5] | O40: 24–20 01000 rs2 | P40: 19–15 11100 rs1 | Q40: 14–12 000 funct3 | R40: 11–8 1010 imm[4:1] | S40: 7 0 imm[11] | T40: 6–0 1100011 opcode
A41: 33 | B41: 0x00000080 | C41: 0x03400413 | D41: addi s0, zero, 52 | E41: addi | F41: I | G41: 6 | H41: 52 | I41: — | J41: 00000011010000000000010000010011 | K41: s0 ← zero + (+52); арифметика RV32I по модулю 2³². | L41: FETCH был | M41: 31–20 000000110100 imm[11:0] | N41: 19–15 00000 rs1 | O41: 14–12 000 funct3 | P41: 11–7 01000 rd | Q41: 6–0 0010011 opcode
A42: 34 | B42: 0x00000084 | C42: 0x048E0C63 | D42: beq t3, s0, 0x000000dc | E42: beq | F42: B | G42: 6 | H42: 88 | I42: 0x000000DC | J42: 00000100100011100000110001100011 | K42: Если t3 = s0, PC ← 0x000000DC; иначе PC ← PC+4. Смещение +88 байт. | L42: FETCH был | M42: 31 0 imm[12] | N42: 30–25 000010 imm[10:5] | O42: 24–20 01000 rs2 | P42: 19–15 11100 rs1 | Q42: 14–12 000 funct3 | R42: 11–8 1100 imm[4:1] | S42: 7 0 imm[11] | T42: 6–0 1100011 opcode
A43: 35 | B43: 0x00000088 | C43: 0x03500413 | D43: addi s0, zero, 53 | E43: addi | F43: I | G43: 6 | H43: 53 | I43: — | J43: 00000011010100000000010000010011 | K43: s0 ← zero + (+53); арифметика RV32I по модулю 2³². | L43: FETCH был | M43: 31–20 000000110101 imm[11:0] | N43: 19–15 00000 rs1 | O43: 14–12 000 funct3 | P43: 11–7 01000 rd | Q43: 6–0 0010011 opcode
...

Sheet РАЗБОР RV32I
A1: LAB-03 / ДЕКОДЕР RISC-V · 32 БИТА
A3: Переключатель «ТРАССА» привязан к ПУЛЬТУ. «РОМ» даёт доступ ко всем 202 рабочим словам. Поля и биты не придуманы — извлечены из конкретных машинных кодов.
A4: СТАРТ | B4: НАБЛЮДЕНИЕ | C4: СРАВНЕНИЕ | D4: LED / MMIO | E4: КОМАНДЫ | F4: 12 ТРАСС | G4: RAW T3 | H4: ROM | I4: ТЕРМИНЫ | J4: ПРОИСХОЖДЕНИЕ | K4: БИТЫ 202 | L4: 10 КАРТОЧЕК
B5: НАСТРОЙКА · выберите источник команды и номер слова программы
B6: № слова ROM (1…202) | D6: 65 | F6: Источник | H6: ТРАССА
B7: Выбранный PC | D7: =IF($H$6="ТРАССА",IF('ПУЛЬТ'!$D$12="FETCH",'ПУЛЬТ'!$D$13,""),IFERROR(INDEX('КАТАЛОГ БИТОВ'!$B$9:$B$210,$D$6),"")) -> 0x00000100 | F7: № по ROM | H7: =IF($D$7="","",IFERROR(MATCH($D$7,'КАТАЛОГ БИТОВ'!$B$9:$B$210,0),"")) -> 65
B9: Машинное слово | D9: =IF($H$7="","",IFERROR(INDEX('КАТАЛОГ БИТОВ'!$C$9:$C$210,$H$7),"")) -> 0x01D2A023 | F9: Команда / формат | H9: =IF($H$7="","",IFERROR(INDEX('КАТАЛОГ БИТОВ'!$E$9:$E$210,$H$7),"")) -> sw | I9: =IF($H$7="","",IFERROR(INDEX('КАТАЛОГ БИТОВ'!$F$9:$F$210,$H$7),"")) -> S
B10: Инструкция ASM | D10: =IF($H$7="","",IFERROR(INDEX('КАТАЛОГ БИТОВ'!$D$9:$D$210,$H$7),"")) -> sw t4, 0(t0)
B11: Статус по трассам | D11: =IF($H$7="","",IFERROR(INDEX('КАТАЛОГ БИТОВ'!$L$9:$L$210,$H$7),"")) -> FETCH был | F11: FETCH в 12 RAW | H11: =IF($H$7="","",IFERROR(INDEX('КАТАЛОГ БИТОВ'!$G$9:$G$210,$H$7),"")) -> 12
B13: ПОБИТОВЫЙ РАЗБОР · точное расположение полей в машинном слове [31:0]
B15: =IF($H$7="","",IFERROR(INDEX('КАТАЛОГ БИТОВ'!$M$9:$M$210,$H$7),"")) -> 31–25 0000000 imm[11:5] | C15: =IF($H$7="","",IFERROR(INDEX('КАТАЛОГ БИТОВ'!$N$9:$N$210,$H$7),"")) -> 24–20 11101 rs2 | D15: =IF($H$7="","",IFERROR(INDEX('КАТАЛОГ БИТОВ'!$O$9:$O$210,$H$7),"")) -> 19–15 00101 rs1 | E15: =IF($H$7="","",IFERROR(INDEX('КАТАЛОГ БИТОВ'!$P$9:$P$210,$H$7),"")) -> 14–12 010 funct3 | F15: =IF($H$7="","",IFERROR(INDEX('КАТАЛОГ БИТОВ'!$Q$9:$Q$210,$H$7),"")) -> 11–7 00000 imm[4:0] | G15: =IF($H$7="","",IFERROR(INDEX('КАТАЛОГ БИТОВ'!$R$9:$R$210,$H$7),"")) -> 6–0 0100011 opcode | H15: =IF($H$7="","",IFERROR(INDEX('КАТАЛОГ БИТОВ'!$S$9:$S$210,$H$7),"")) | I15: =IF($H$7="","",IFERROR(INDEX('КАТАЛОГ БИТОВ'!$T$9:$T$210,$H$7),""))
B17: ПОЛЯ: что означает каждое значение в данной инструкции
B19: 01 | C19: =IF($H$7="","",IFERROR(INDEX('КАТАЛОГ БИТОВ'!$M$9:$M$210,$H$7),"")) -> 31–25 0000000 imm[11:5] | E19: =IF($H$7="","",IFERROR(INDEX('КАТАЛОГ ОПИСАНИЙ'!$B$9:$B$210,$H$7),"")) -> Старшие биты смещения со знаком
B20: 02 | C20: =IF($H$7="","",IFERROR(INDEX('КАТАЛОГ БИТОВ'!$N$9:$N$210,$H$7),"")) -> 24–20 11101 rs2 | E20: =IF($H$7="","",IFERROR(INDEX('КАТАЛОГ ОПИСАНИЙ'!$C$9:$C$210,$H$7),"")) -> Источник записываемых данных: x29 = t4
B21: 03 | C21: =IF($H$7="","",IFERROR(INDEX('КАТАЛОГ БИТОВ'!$O$9:$O$210,$H$7),"")) -> 19–15 00101 rs1 | E21: =IF($H$7="","",IFERROR(INDEX('КАТАЛОГ ОПИСАНИЙ'!$D$9:$D$210,$H$7),"")) -> Базовый адрес: x5 = t0
B22: 04 | C22: =IF($H$7="","",IFERROR(INDEX('КАТАЛОГ БИТОВ'!$P$9:$P$210,$H$7),"")) -> 14–12 010 funct3 | E22: =IF($H$7="","",IFERROR(INDEX('КАТАЛОГ ОПИСАНИЙ'!$E$9:$E$210,$H$7),"")) -> 010 = SW: запись 32-битного слова
B23: 05 | C23: =IF($H$7="","",IFERROR(INDEX('КАТАЛОГ БИТОВ'!$Q$9:$Q$210,$H$7),"")) -> 11–7 00000 imm[4:0] | E23: =IF($H$7="","",IFERROR(INDEX('КАТАЛОГ ОПИСАНИЙ'!$F$9:$F$210,$H$7),"")) -> Младшие биты смещения
B24: 06 | C24: =IF($H$7="","",IFERROR(INDEX('КАТАЛОГ БИТОВ'!$R$9:$R$210,$H$7),"")) -> 6–0 0100011 opcode | E24: =IF($H$7="","",IFERROR(INDEX('КАТАЛОГ ОПИСАНИЙ'!$G$9:$G$210,$H$7),"")) -> 0100011: STORE
B25: 07 | C25: =IF($H$7="","",IFERROR(INDEX('КАТАЛОГ БИТОВ'!$S$9:$S$210,$H$7),"")) | E25: =IF($H$7="","",IFERROR(INDEX('КАТАЛОГ ОПИСАНИЙ'!$H$9:$H$210,$H$7),""))
B26: 08 | C26: =IF($H$7="","",IFERROR(INDEX('КАТАЛОГ БИТОВ'!$T$9:$T$210,$H$7),"")) | E26: =IF($H$7="","",IFERROR(INDEX('КАТАЛОГ ОПИСАНИЙ'!$I$9:$I$210,$H$7),""))
B28: ОБЪЯСНЕНИЕ ИНСТРУКЦИИ В НАШЕЙ ПРОГРАММЕ
B29: =IF($H$7="","",IFERROR(INDEX('КАТАЛОГ БИТОВ'!$K$9:$K$210,$H$7),"")) -> MEM32[t0 +0] ← t4. Число, находящееся в rs2, не кодируется в самой инструкции.
B32: ИНЖЕНЕРНАЯ ГРАНИЦА
B33: FETCH означает принятый запрос слова из ROM — НЕ доказательство instruction retirement. Значения регистров при FETCH не измеряются. Если выбран LED_WRITE, это событие MMIO, а не инструкция: вернитесь на FETCH.

Sheet 10 КАРТОЧЕК
A1: LAB-03 / 10 МНЕМОНИК НА РЕАЛЬНЫХ МАШИННЫХ СЛОВАХ
A3: Один подлинный пример каждой встречающейся в LAB-03 мнемоники. 6 встречались среди 269 FETCH, 4 имеются только в активной ROM. R-type в этой программе нет.
A4: СТАРТ | B4: НАБЛЮДЕНИЕ | C4: СРАВНЕНИЕ | D4: LED / MMIO | E4: КОМАНДЫ | F4: 12 ТРАСС | G4: RAW T3 | H4: ROM | I4: ТЕРМИНЫ | J4: ПРОИСХОЖДЕНИЕ | K4: БИТЫ 202 | L4: 10 КАРТОЧЕК
B7: 01 SW • Store Word | PC=0x00000100 | НАБЛЮДАЛОСЬ НА FPGA
B8: 0x01D2A023 sw t4, 0(t0) · S-type / S
B9: Записать 32-битное значение rs2 по адресу rs1+imm.
B10: 31–25 | C10: 24–20 | D10: 19–15 | E10: 14–12 | F10: 11–7 | G10: 6–0
B11: 0000000 | C11: 11101 | D11: 00101 | E11: 010 | F11: 00000 | G11: 0100011
B12: imm[11:5] | C12: rs2 | D12: rs1 | E12: funct3 | F12: imm[4:0] | G12: opcode
B13: S-format / смещение: 0 | MEM32[t0 +0] ← t4. Число, находящееся в rs2, не кодируется в самой инструкции.
B14: Роль в LAB-03: PC=0x100 пишет выбранную LED-маску в MMIO 0x20000000. | FETCH этого PC в архиве: 12
B18: 02 LW • Load Word | PC=0x00000104 | НАБЛЮДАЛОСЬ НА FPGA
B19: 0x0002AF83 lw t6, 0(t0) · I-type / I
B20: Загрузить 32-битное слово из памяти/MMIO по rs1+imm в rd.
B21: 31–20 | C21: 19–15 | D21: 14–12 | E21: 11–7 | F21: 6–0
B22: 000000000000 | C22: 00101 | D22: 010 | E22: 11111 | F22: 0000011
B23: imm[11:0] | C23: rs1 | D23: funct3 | E23: rd | F23: opcode
B24: I-format / смещение: 0 | t6 ← MEM32[t0 +0]. FETCH этой инструкции не удостоверяет регистрацию DATA_READ.
B25: Роль в LAB-03: Читает регистры UART и LED; FETCH lw не является наблюдением DATA_READ. | FETCH этого PC в архиве: 12
B29: 03 ADDI • Add Immediate | PC=0x00000048 | НАБЛЮДАЛОСЬ НА FPGA
B30: 0x05400413 addi s0, zero, 84 · I-type / I
B31: Сложить значение rs1 со знаковой 12-битной константой и записать в rd.
B32: 31–20 | C32: 19–15 | D32: 14–12 | E32: 11–7 | F32: 6–0
B33: 000001010100 | C33: 00000 | D33: 000 | E33: 01000 | F33: 0010011
B34: imm[11:0] | C34: rs1 | D34: funct3 | E34: rd | F34: opcode
B35: I-format / смещение: 84 | s0 ← zero + (+84); арифметика RV32I по модулю 2³².
B36: Роль в LAB-03: Подготавливает UART-символы, маски GPIO и промежуточные значения. | FETCH этого PC в архиве: 12
B40: 04 ANDI • AND Immediate | PC=0x0000003C | НАБЛЮДАЛОСЬ НА FPGA
B41: 0x0013F393 andi t2, t2, 1 · I-type / I
B42: Побитовое И значения rs1 со знаковой 12-битной константой.
B43: 31–20 | C43: 19–15 | D43: 14–12 | E43: 11–7 | F43: 6–0
B44: 000000000001 | C44: 00111 | D44: 111 | E44: 00111 | F44: 0010011
B45: imm[11:0] | C45: rs1 | D45: funct3 | E45: rd | F45: opcode
B46: I-format / смещение: 1 | t2 ← t2 AND (+1); побитовое И с sign_extend(imm).
B47: Роль в LAB-03: Отделяет бит готовности при опросе UART. | FETCH этого PC в архиве: 11
B51: 05 BEQ • Branch if Equal | PC=0x00000040 | НАБЛЮДАЛОСЬ НА FPGA
B52: 0xFE038CE3 beq t2, zero, 0x00000038 · B-type / B
B53: Если значения двух регистров равны, изменить PC на заданное смещение.
B54: 31 | C54: 30–25 | D54: 24–20 | E54: 19–15 | F54: 14–12 | G54: 11–8 | H54: 7 | I54: 6–0
B55: 1 | C55: 111111 | D55: 00000 | E55: 00111 | F55: 000 | G55: 1100 | H55: 1 | I55: 1100011
...

Sheet ПУЛЬТ
A1: ПУЛЬТ / АППАРАТНАЯ ТРАССА
A3: Выбирайте № захвата и № события в жёлтых ячейках • Excel отображает сохранённые измерения, не опрашивает USB
A4: СТАРТ | B4: НАБЛЮДЕНИЕ | C4: СРАВНЕНИЕ | D4: LED / MMIO | E4: КОМАНДЫ | F4: 12 ТРАСС | G4: RAW T3 | H4: ROM | I4: ТЕРМИНЫ | J4: ПРОИСХОЖДЕНИЕ | K4: БИТЫ 202 | L4: 10 КАРТОЧЕК
B6: Захват № | D6: 5 | G6: Событие № | I6: 27
B7: Команда UART | D7: =IFERROR(INDEX('ЗАХВАТЫ'!$B$6:$B$17,MATCH(D6,'ЗАХВАТЫ'!$A$6:$A$17,0)),"") -> 4 | G7: Событий в захвате | I7: =IFERROR(INDEX('ЗАХВАТЫ'!$E$6:$E$17,MATCH(D6,'ЗАХВАТЫ'!$A$6:$A$17,0)),0) -> 29
B8: Всего FETCH | D8: =IFERROR(INDEX('ЗАХВАТЫ'!$D$6:$D$17,MATCH(D6,'ЗАХВАТЫ'!$A$6:$A$17,0)),0) -> 28 | G8: CORE FETCH | I8: =IFERROR(INDEX('ЗАХВАТЫ'!$H$6:$H$17,MATCH(D6,'ЗАХВАТЫ'!$A$6:$A$17,0)),0) -> 22
B9: Polling-префикс | D9: =IFERROR(INDEX('ЗАХВАТЫ'!$G$6:$G$17,MATCH(D6,'ЗАХВАТЫ'!$A$6:$A$17,0)),0) -> 6 | G9: Якорь сравнения | I9: PC=0x00000048
A11: ИНСПЕКТОР ВЫБРАННОГО СОБЫТИЯ
B12: Тип | D12: =IFERROR(INDEX('ДАННЫЕ T3'!$E$6:$E$286,MATCH($D$6*1000+$I$6,'ДАННЫЕ T3'!$K$6:$K$286,0)),"") -> FETCH | G12: Цикл T3 | I12: =IFERROR(INDEX('ДАННЫЕ T3'!$D$6:$D$286,MATCH($D$6*1000+$I$6,'ДАННЫЕ T3'!$K$6:$K$286,0)),"") -> 108
B13: PC / адрес | D13: =IFERROR(INDEX('ДАННЫЕ T3'!$F$6:$F$286,MATCH($D$6*1000+$I$6,'ДАННЫЕ T3'!$K$6:$K$286,0)),"") -> 0x00000100 | G13: WORD / DATA | I13: =IFERROR(INDEX('ДАННЫЕ T3'!$G$6:$G$286,MATCH($D$6*1000+$I$6,'ДАННЫЕ T3'!$K$6:$K$286,0)),"") -> 0x01D2A023
B14: Мнемоника | D14: =IFERROR(INDEX('ДАННЫЕ T3'!$I$6:$I$286,MATCH($D$6*1000+$I$6,'ДАННЫЕ T3'!$K$6:$K$286,0)),"") -> sw | G14: Участок | I14: =IFERROR(INDEX('ДАННЫЕ T3'!$J$6:$J$286,MATCH($D$6*1000+$I$6,'ДАННЫЕ T3'!$K$6:$K$286,0)),"") -> CORE
B15: Дизассемблирование | D15: =IFERROR(INDEX('ДАННЫЕ T3'!$H$6:$H$286,MATCH($D$6*1000+$I$6,'ДАННЫЕ T3'!$K$6:$K$286,0)),"") -> sw t4, 0(t0)
B17: Что означает | D17: =IF(D12="LED_WRITE","Аппаратная шина приняла запись GPIO по адресу 0x20000000",IFERROR(VLOOKUP(D14,'КОМАНДЫ'!$A$7:$F$17,5,FALSE),"Выберите событие")) -> MEM32[rs1 + offset] ← rs2
B20: К этому шагу LED | D20: =IF(D12="LED_WRITE",I13,"Ещё нет LED_WRITE") -> Ещё нет LED_WRITE | G20: Итог снимка | I20: =IFERROR(INDEX('ЗАХВАТЫ'!$F$6:$F$17,MATCH(D6,'ЗАХВАТЫ'!$A$6:$A$17,0)),"") -> 0x00000008
